<!DOCTYPE html>
<html lang="en">
  <head>
    <meta charset="UTF-8" />
    <meta name="viewport" content="width=device-width, initial-scale=1.0" />
    <title>Document</title>
  </head>
  <body>
    <script>
      function runAsyncTask(callback) {
        if (typeof queueMicrotask === "function") {
          queueMicrotask(callback);
        } else if (typeof MutationObserver === "function") {
          const observer = new MutationObserver(callback);
          const div = document.createElement("div");
          observer.observe(div, { childList: true });
          div.innerText = "hello";
        } else {
          setTimeout(callback, 0);
        }
      }

      function handleReturnValue(returnValue, p2, resovle, reject) {
        // 如果返回值和then方法返回的promise是同一个
        if (returnValue === p2) {
          throw new TypeError("Chaining cycle detected for promise #<Promise>");
        }
        // 如果返回值是MyPromise实例
        if (returnValue instanceof MyPromise) {
          returnValue.then(
            (res) => resovle(res),
            (error) => reject(error)
          );
        } else {
          // 如果不是MyPromise实例
          resovle(returnValue);
        }
      }
      // 自定义Promise对象
      // Promise对象：获取异步操作结果的
      // 1. 传入一个回调函数，该回调函数接收两个参数(resolve,reject)
      // 2. Promise对象有三个状态：pedding/ fullfilled / rejected，状态的改变是单向的
      // 2.1 当使用者在回调函数内进行异步操作，异步操作成功可以通过调用resolve（）返回成功的结果，并修改状态为pedding =》fullfilled
      // 2.1 当使用者在回调函数内进行异步操作，异步操作失败可以通过调用reject（）返回成功的结果，并修改状态为pedding =》rejected
      // 3. 实例方法：then/catch
      // 3.1 通过调用.then方法resovle函数获取同步/异步操作成功/失败的结果

      // const p1 = new Promise((resovle, reject) => {
      //   setTimeout(() => {
      //     resovle("100");
      //   }, 1000);
      // });
      // p1.then((value) => {
      //   console.log("success:", value);
      // }).catch((resson) => {
      //   console.log("fail:", resson);
      // });
      // console.log("p1:", p1);

      // 状态变量
      // option + 双击选中三个变量名
      // cmd+shift+p 转为大写
      const FULLFILLED = "fullfilled";
      const PENDDING = "pedding";
      const REJECTED = "rejected";
      class MyPromise {
        // 状态
        state = PENDDING;
        // 结果
        result = undefined;

        // promise成功/失败的回调函数
        #onFullfilledCallBacks = [];
        #onRejectedCallBacks = [];
        // 传入回调函数
        constructor(excutorFn) {
          // 1. 两个内函数(这里是箭头函数)
          // 箭头函数内部的this指向箭头函数定义所在上下文的this
          // 也就是 this指向的Promise 实例
          const resovle = (result) => {
            // 1.1 state是不可逆的
            if (this.state === PENDDING) {
              this.state = FULLFILLED;
              this.result = result;
              // 异步操作：当状态改变时，执行成功的回调函数
              this.#onFullfilledCallBacks.forEach((onFullfilled) => {
                runAsyncTask(() => {
                  onFullfilled(this.result);
                });
              });
            }
          };
          const reject = (result) => {
            if (this.state === PENDDING) {
              this.state = REJECTED;
              this.result = result;
              // 异步操作：当状态改变时，执行失败的回调函数
              this.#onRejectedCallBacks.forEach((onRejected) => {
                runAsyncTask(() => {
                  onRejected(this.result);
                });
              });
            }
          };

          // 执行回调函数
          excutorFn(resovle, reject);
        }

        // 2. 实例方法then方法
        // .then((res,error)=>{})
        then(onFullfilled, onRejected) {
          onFullfilled =
            typeof onFullfilled === "function" ? onFullfilled : (x) => x;
          onRejected =
            typeof onRejected === "function"
              ? onRejected
              : (x) => {
                  throw x;
                };

          // 返回Promise，支持链式调用
          const p2 = new MyPromise((resovle, reject) => {
            // 同步操作，直接执行
            if (this.state === FULLFILLED) {
              runAsyncTask(() => {
                // 处理onFullfilled返回值以及抛出的异常
                try {
                  const returnValue = onFullfilled(this.result);

                  // 如果返回值跟then方法返回promise是同一个
                  if (returnValue === p2) {
                    throw new TypeError(
                      "Chaining cycle detected for promise #<Promise>"
                    );
                  }
                  // 如果返回值是MyPromise实例
                  if (returnValue instanceof MyPromise) {
                    returnValue.then(
                      (res) => resovle(res),
                      (error) => reject(error)
                    );
                  } else {
                    // 如果不是MyPromise实例
                    resovle(returnValue);
                  }
                } catch (error) {
                  reject(error);
                }
              });
            }
            if (this.state === REJECTED) {
              runAsyncTask(() => {
                // 处理抛出的异常
                try {
                  const returnValue = onRejected(this.result);
                  // 处理返回值
                  handleReturnValue(returnValue, p2, resovle, reject);
                } catch (error) {
                  reject(error);
                }
              });
            }
            // 异步操作：先保存成功/失败的回调函数
            if (this.state === PENDDING) {
              this.#onFullfilledCallBacks.push(onFullfilled);
              this.#onRejectedCallBacks.push(onRejected);
            }
          });

          return p2;
        }
      }

      // 测试1: 状态是不可逆的，只能从pedding->resolved 或者peddding->rejected
      // 不能从 resolved=>rejected rejected=>resolved

      // const p2 = new MyPromise((resolve, reject) => {
      //   // 目前还不支持获取异步操作结果：state，result不会更新
      //   // setTimeout(() => {
      //   //   resolve("100");
      //   //   // reject("1000");
      //   // }, 1000);
      //       resolve("100");
      //     // reject("1000");
      // });

      // 测试2: 实例方法then，
      // const p2 = new MyPromise((resolve, reject) => {
      //   // 同步操作
      //   resolve(100);
      //   // reject("errorxxx");
      // });
      // 获取同步操作结果，支持接收两个参数
      // p2.then(
      //   (res) => {
      //     console.log(res);
      //   },
      //   (error) => {
      //     console.log(error);
      //   }
      // );

      // 测试3： 调用reject，但是then只接收一个参数时。报错：Uncaught errorxxx
      // p2.then((res) => {
      //   console.log(res);
      // });

      // 测试3， then方法支持获取异步操作结果
      // 需求分析：如果是异步操作，p2.then获取异步操作结果时，resolve(100)还未执行。也就是promise的状态还未改变，这时获取结果是失败的
      // 解决：then时保存回调函数，等到resolve/reject方法被调用时再执行回调函数
      // const p2 = new MyPromise((resolve, reject) => {
      //   // 异步操作
      //   setTimeout(() => {
      //     // resolve(100);
      //     reject("errorxxx");
      //   }, 1000);
      // });
      // p2.then(
      //   (res) => {
      //     console.log(res);
      //   },
      //   (error) => {
      //     console.log(error);
      //   }
      // );
      // p2.then(
      //   (res) => {
      //     console.log("x", res);
      //   },
      //   (error) => {
      //     console.log("x", error);
      //   }
      // );

      // 测试5：.then支持异步任务
      // 分析： 原生Promise，执行顺序是top,bottom, 100
      // 可见，原生Promise是将then方法的成功/失败的回调函数放到异步任务中执行的
      // console.log("1");
      // const p2 = new Promise((resolve, reject) => {
      //   resolve(2);
      // });
      // p2.then((res) => {
      //   console.log(res);
      // });
      // console.log("3");

      // console.log("1");
      // const p2 = new MyPromise((resolve, reject) => {
      //   // resolve(2);
      //   setTimeout(() => {
      //     reject(2);
      //   }, 0);
      // });
      // p2.then(
      //   (res) => {
      //     console.log(res);
      //   },
      //   (error) => {
      //     console.log(error);
      //   }
      // );
      // console.log("3");

      // 测试6: then方法支持链式调用
      // 如何做呢？
      // 1. 返回新的Promise
      // 1.1 处理成功的回调函数onFullfilled方法的返回值，传给下一个then的onFullfilled函数
      // 1.2 处理成功的回调函数onFullfilled方法抛出的异常,传给下一个then的onRejected函数
      // const p2 = new MyPromise((resolve, reject) => {
      //   resolve(1);
      //   // reject(2);
      // });
      // p2.then(
      //   (res) => {
      //     console.log("p1 res:", res);
      //     throw "xxxx error";
      //     return 2;
      //   },
      //   (error) => {
      //     console.log("p1 error:", error);
      //   }
      // ).then(
      //   (res) => {
      //     console.log("p2 res", res);
      //   },
      //   (error) => {
      //     console.log("p2 error", error);
      //   }
      // );

      // 测试6：then方法支持链式调用，onFullfilled方法支持返回Promise
      // const p2 = new MyPromise((resolve, reject) => {
      //   resolve(1);
      //   // reject(2);
      // });
      // p2.then(
      //   (res) => {
      //     console.log("p1 res:", res);
      //     return new MyPromise((resovle, reject) => {
      //       reject(22);
      //     });
      //   },
      //   (error) => {
      //     console.log("p1 error:", error);
      //   }
      // ).then(
      //   (res) => {
      //     console.log("p2 res", res);
      //   },
      //   (error) => {
      //     console.log("p2 error", error);
      //   }
      // );

      // 测试7：then方法支持链式调用,如果onFullfilled回调函数返回的MyPromise实例和then方法返回的MyPromise实例是同一个时，支持抛出TypeError
      // 分析：原生Promise，then方法onFullfilled回调函数返回的Promise实例和then方法返回的Promise实例是同一个时
      // 会抛出TypeError：Uncaught (in promise) TypeError: Chaining cycle detected for promise #<Promise>

      // const p = new Promise((resovle, reject) => {
      //   resovle("xxx");
      // }).then((res) => {
      //   console.log("p:", res);
      //   return p;
      // });

      // const p = new MyPromise((resolve, reject) => {
      //   resolve(1);
      //   // reject(2);
      // });

      // const p2 = p.then(
      //   (res) => {
      //     console.log("p1 res:", res);
      //     return p2;
      //   },
      //   (error) => {
      //     console.log("p1 error:", error);
      //   }
      // );
      // p2.then(
      //   () => {},
      //   (err) => {
      //     console.log(err);
      //   }
      // );

      // 测试8: then方法支持链式调用,处理失败的回调函数onRejected
      // 处理onRejected函数内抛出的异常
      // - 处理onRejected函数返回值
      // -- 返回值是普通值
      // -- 返回值是Promise对象
      // -- 返回值跟then方法返回值是同一个实例的问题

      const p = new MyPromise((resolve, reject) => {
        reject(2);
      });
      const p2 = p.then(
        (res) => {
          console.log("p1 res:", res);
        },
        (error) => {
          // throw "xxxxx";
          return 1;
          // return new MyPromise((resovle, reject) => {
          //   // reject(22);
          //   resovle(11);
          // });
          // return p2;
          // console.log("p1 error:", error);
        }
      );
      p2.then(
        (res) => {
          console.log("p2 res", res);
        },
        (error) => {
          console.log("p2 error", error);
        }
      );
    </script>
  </body>
</html>
